2024-03-19 21:08:32,006 ERROR: Exception on /user/Sam [GET] [in D:\dev\software\miniconda3\envs\dbwe\lib\site-packages\flask\app.py:1414]
Traceback (most recent call last):
  File "D:\dev\software\miniconda3\envs\dbwe\lib\site-packages\flask\app.py", line 2190, in wsgi_app
    response = self.full_dispatch_request()
  File "D:\dev\software\miniconda3\envs\dbwe\lib\site-packages\flask\app.py", line 1486, in full_dispatch_request
    rv = self.handle_user_exception(e)
  File "D:\dev\software\miniconda3\envs\dbwe\lib\site-packages\flask\app.py", line 1484, in full_dispatch_request
    rv = self.dispatch_request()
  File "D:\dev\software\miniconda3\envs\dbwe\lib\site-packages\flask\app.py", line 1469, in dispatch_request
    return self.ensure_sync(self.view_functions[rule.endpoint])(**view_args)
  File "D:\dev\software\miniconda3\envs\dbwe\lib\site-packages\flask_login\utils.py", line 290, in decorated_view
    return current_app.ensure_sync(func)(*args, **kwargs)
  File "D:\dev\workspace\iten-engineering\dbwe\flask\blog10\blog.py", line 157, in user
    posts = ds.posts()
NameError: name 'ds' is not defined
